Workbook

Sheet base
C2: Tipo | D2: Massa | E2: Molho de tomate | F2: Queijo | G2: Rucula | H2: Parma | I2: Bacon | J2: Cream chease | K2: Catupiry | L2: Tomate | M2: Manjericão | N2: Milho | O2: Frango | P2: Mussarela de bufula | Q2: azeitona | R2: nutela | S2: banana | T2: goiabada | U2: calabresa | V2: abobrinha | W2: peperoni | X2: mortadela | Y2: pistache | Z2: pernil de porco | AA2: qualhada | AB2: fraldinha | AC2: gorgonzola | AD2: doce leite | AG2: Total por pizza
C3: Parma com rucula | D3: 300 | E3: 60 | F3: 150 | G3: 50 | H3: 150 | AG3: =SUM(F3:AF3)-G3 -> 300
C4: marguerita | D4: 300 | E4: 60 | F4: 200 | L4: 70 | M4: 50 | AG4: =SUM(F4:AF4)-G4 -> 320
C5: Corn bacon | D5: 300 | E5: 60 | F5: 150 | I5: 75 | N5: 65 | AG5: =SUM(F5:AF5)-G5 -> 290
C6: philadelfia | D6: 300 | E6: 60 | F6: 150 | I6: 75 | J6: 75 | L6: 70 | AG6: =SUM(F6:AF6)-G6 -> 370
C7: frango catupiry | D7: 300 | E7: 60 | F7: 150 | K7: 75 | O7: 150 | AG7: =SUM(F7:AF7)-G7 -> 375
C8: Caprese | D8: 300 | E8: 60 | F8: 150 | L8: 70 | P8: 100 | Q8: 100 | AG8: =SUM(F8:AF8)-G8 -> 420
C9: banana com nutela | D9: 300 | R9: 150 | S9: 100 | AG9: =SUM(F9:AF9)-G9 -> 250
C10: romeu julieta | D10: 300 | F10: 150 | T10: 200 | AG10: =SUM(F10:AF10)-G10 -> 350
C11: calabresa | D11: 300 | E11: 60 | F11: 150 | U11: 150 | AG11: =SUM(F11:AF11)-G11 -> 300
C12: zuquine | D12: 300 | E12: 60 | F12: 150 | V12: 200 | AG12: =SUM(F12:AF12)-G12 -> 350
C13: peperoni | D13: 300 | E13: 60 | F13: 150 | W13: 150 | AG13: =SUM(F13:AF13)-G13 -> 300
C14: crostine | D14: 300 | AG14: =SUM(F14:AF14)-G14 -> 0
C15: montandela | D15: 300 | E15: 60 | F15: 150 | X15: 210 | Y15: 15 | AA15: 100 | AG15: =SUM(F15:AF15)-G15 -> 475
C16: Pernil | D16: 300 | E16: 60 | F16: 150 | T16: 50 | Z16: 200 | AG16: =SUM(F16:AF16)-G16 -> 400
C17: fraldinha | D17: 300 | E17: 60 | F17: 150 | AB17: 200 | AC17: 50 | AG17: =SUM(F17:AF17)-G17 -> 400
C18: banana doce de leite | D18: 300 | S18: 200 | AD18: 150 | AG18: =SUM(F18:AF18)-G18 -> 350
C21: total | D21: =SUM(D3:D20) -> 4800 | E21: =SUM(E3:E20) -> 720 | F21: =SUM(F3:F20) -> 2000 | G21: =SUM(G3:G14) -> 50 | H21: =SUM(H3:H14) -> 150 | I21: =SUM(I3:I14) -> 150 | J21: =SUM(J3:J14) -> 75 | K21: =SUM(K3:K14) -> 75 | L21: =SUM(L3:L14) -> 210 | M21: =SUM(M3:M14) -> 50 | N21: =SUM(N3:N14) -> 65 | ... S21: =SUM(S3:S14) -> 100 | T21: =SUM(T3:T20) -> 250 | U21: =SUM(U3:U20) -> 150 | V21: =SUM(V3:V20) -> 200 | W21: =SUM(W3:W20) -> 150 | X21: =SUM(X3:X20) -> 210 | Y21: =SUM(Y3:Y20) -> 15 | Z21: =SUM(Z3:Z20) -> 200 | AA21: =SUM(AA3:AA20) -> 100 | ... AF21: =SUM(AF3:AF20) -> 0 | AG21: =SUM(G21:P21) -> 1075
C26: aqui montas as pizza

Sheet final
D1: aqui ele so pega da base e multiplica os ingredientes
B2: Tipo | C2: Massa | D2: Molho de tomate | E2: Queijo | F2: Rucula | G2: Parma | H2: Bacon | I2: Cream chease | J2: Catupiry | K2: Tomate | L2: Manjericão | M2: Milho | N2: Frango | O2: Mussarela de bufula | P2: azeitona | Q2: nutela | R2: banana | S2: goiabada | T2: calabresa | U2: abobrinha | V2: peperoni | W2: mortadela | X2: pistache | Y2: pernil de porco | Z2: qualhada | AA2: fraldinha | AB2: gorgonzola | AC2: doce leite | AE2: Total por pizza | AF2: media
B3: Parma com rucula | C3: =$F$26*base!D3 -> 0 | D3: =$F$26*base!E3 -> 0 | E3: =$F$26*base!F3 -> 0 | F3: =$F$26*base!G3 -> 0 | G3: =$F$26*base!H3 -> 0 | H3: =$F$26*base!I3 -> 0 | I3: =$F$26*base!J3 -> 0 | J3: =$F$26*base!K3 -> 0 | ... AC3: =$F$26*base!AD3 -> 0 | AE3: =SUM(C3:R3) -> 0
B4: marguerita | C4: =$F$27*base!D4 -> 600 | D4: =$F$27*base!E4 -> 120 | E4: =$F$27*base!F4 -> 400 | F4: =$F$27*base!G4 -> 0 | G4: =$F$27*base!H4 -> 0 | H4: =$F$27*base!I4 -> 0 | I4: =$F$27*base!J4 -> 0 | J4: =$F$27*base!K4 -> 0 | ... AC4: =$F$27*base!AD4 -> 0 | AE4: =SUM(C4:R4) -> 1360
B5: Corn bacon | C5: =$F$28*base!D5 -> 600 | D5: =$F$28*base!E5 -> 120 | E5: =$F$28*base!F5 -> 300 | F5: =$F$28*base!G5 -> 0 | G5: =$F$28*base!H5 -> 0 | H5: =$F$28*base!I5 -> 150 | I5: =$F$28*base!J5 -> 0 | J5: =$F$28*base!K5 -> 0 | ... AC5: =$F$28*base!AD5 -> 0 | AE5: =SUM(C5:R5) -> 1300
B6: philadelfia | C6: =$F$29*base!D6 -> 600 | D6: =$F$29*base!E6 -> 120 | E6: =$F$29*base!F6 -> 300 | F6: =$F$29*base!G6 -> 0 | G6: =$F$29*base!H6 -> 0 | H6: =$F$29*base!I6 -> 150 | I6: =$F$29*base!J6 -> 150 | J6: =$F$29*base!K6 -> 0 | ... AC6: =$F$29*base!AD6 -> 0 | AE6: =SUM(C6:R6) -> 1460
B7: frango catupiry | C7: =$F$30*base!D7 -> 0 | D7: =$F$30*base!E7 -> 0 | E7: =$F$30*base!F7 -> 0 | F7: =$F$30*base!G7 -> 0 | G7: =$F$30*base!H7 -> 0 | H7: =$F$30*base!I7 -> 0 | I7: =$F$30*base!J7 -> 0 | J7: =$F$30*base!K7 -> 0 | ... AC7: =$F$30*base!AD7 -> 0 | AE7: =SUM(C7:R7) -> 0
B8: Caprese | C8: =$F$31*base!D8 -> 0 | D8: =$F$31*base!E8 -> 0 | E8: =$F$31*base!F8 -> 0 | F8: =$F$31*base!G8 -> 0 | G8: =$F$31*base!H8 -> 0 | H8: =$F$31*base!I8 -> 0 | I8: =$F$31*base!J8 -> 0 | J8: =$F$31*base!K8 -> 0 | ... AC8: =$F$31*base!AD8 -> 0 | AE8: =SUM(C8:R8) -> 0
B9: banana com nutela | C9: =$F$32*base!D9 -> 900 | D9: =$F$32*base!E9 -> 0 | E9: =$F$32*base!F9 -> 0 | F9: =$F$32*base!G9 -> 0 | G9: =$F$32*base!H9 -> 0 | H9: =$F$32*base!I9 -> 0 | I9: =$F$32*base!J9 -> 0 | J9: =$F$32*base!K9 -> 0 | ... AC9: =$F$32*base!AD9 -> 0 | AE9: =SUM(C9:R9) -> 1650
B10: romeu julieta | C10: =$F$33*base!D10 -> 0 | D10: =$F$33*base!E10 -> 0 | E10: =$F$33*base!F10 -> 0 | F10: =$F$33*base!G10 -> 0 | G10: =$F$33*base!H10 -> 0 | H10: =$F$33*base!I10 -> 0 | I10: =$F$33*base!J10 -> 0 | J10: =$F$33*base!K10 -> 0 | ... AC10: =$F$33*base!AD10 -> 0 | AE10: =SUM(C10:R10) -> 0
B11: calabresa | C11: =$F$34*base!D11 -> 600 | D11: =$F$34*base!E11 -> 120 | E11: =$F$34*base!F11 -> 300 | F11: =$F$34*base!G11 -> 0 | G11: =$F$34*base!H11 -> 0 | H11: =$F$34*base!I11 -> 0 | I11: =$F$34*base!J11 -> 0 | J11: =$F$34*base!K11 -> 0 | ... AC11: =$F$34*base!AD11 -> 0 | AE11: =SUM(C11:V11) -> 1320
B12: zuquine | C12: =$F$35*base!D12 -> 0 | D12: =$F$35*base!E12 -> 0 | E12: =$F$35*base!F12 -> 0 | F12: =$F$35*base!G12 -> 0 | G12: =$F$35*base!H12 -> 0 | H12: =$F$35*base!I12 -> 0 | I12: =$F$35*base!J12 -> 0 | J12: =$F$35*base!K12 -> 0 | ... AC12: =$F$35*base!AD12 -> 0 | AE12: =SUM(C12:R12) -> 0
B13: peperoni | C13: =$F$36*base!D13 -> 0 | D13: =$F$36*base!E13 -> 0 | E13: =$F$36*base!F13 -> 0 | F13: =$F$36*base!G13 -> 0 | G13: =$F$36*base!H13 -> 0 | H13: =$F$36*base!I13 -> 0 | I13: =$F$36*base!J13 -> 0 | J13: =$F$36*base!K13 -> 0 | ... AC13: =$F$36*base!AD13 -> 0 | AE13: =SUM(C13:V13) -> 0
B14: crotine | C14: =$F$37*base!D14 -> 0 | D14: =$F$37*base!E14 -> 0 | E14: =$F$37*base!F14 -> 0 | F14: =$F$37*base!G14 -> 0 | G14: =$F$37*base!H14 -> 0 | H14: =$F$37*base!I14 -> 0 | I14: =$F$37*base!J14 -> 0 | J14: =$F$37*base!K14 -> 0 | ... AC14: =$F$37*base!AD14 -> 0 | AE14: =SUM(C14:R14) -> 0
B15: montandela | C15: =$F$38*base!D15 -> 600 | D15: =$F$38*base!E15 -> 120 | E15: =$F$38*base!F15 -> 300 | F15: =$F$38*base!G15 -> 0 | G15: =$F$38*base!H15 -> 0 | H15: =$F$38*base!I15 -> 0 | I15: =$F$38*base!J15 -> 0 | J15: =$F$38*base!K15 -> 0 | ... AC15: =$F$38*base!AD15 -> 0 | AE15: =SUM(C15:R15) -> 1020
B16: Pernil | C16: =$F$39*base!D16 -> 0 | D16: =$F$39*base!E16 -> 0 | E16: =$F$39*base!F16 -> 0 | F16: =$F$39*base!G16 -> 0 | G16: =$F$39*base!H16 -> 0 | H16: =$F$39*base!I16 -> 0 | I16: =$F$39*base!J16 -> 0 | J16: =$F$39*base!K16 -> 0 | ... AC16: =$F$39*base!AD16 -> 0 | AE16: =SUM(C16:R16) -> 0
B17: fraldinha | C17: =$F$40*base!D17 -> 0 | D17: =$F$40*base!E17 -> 0 | E17: =$F$40*base!F17 -> 0 | F17: =$F$40*base!G17 -> 0 | G17: =$F$40*base!H17 -> 0 | H17: =$F$40*base!I17 -> 0 | I17: =$F$40*base!J17 -> 0 | J17: =$F$40*base!K17 -> 0 | ... AC17: =$F$40*base!AD17 -> 0 | AE17: =SUM(C17:R17) -> 0
B18: banana doce de leite | C18: =$F$41*base!D18 -> 0 | D18: =$F$41*base!E18 -> 0 | E18: =$F$41*base!F18 -> 0 | F18: =$F$41*base!G18 -> 0 | G18: =$F$41*base!H18 -> 0 | H18: =$F$41*base!I18 -> 0 | I18: =$F$41*base!J18 -> 0 | J18: =$F$41*base!K18 -> 0 | ... AC18: =$F$41*base!AD18 -> 0 | AE18: =SUM(C18:R18) -> 0
B21: total | C21: =SUM(C3:C18) -> 3900 | D21: =SUM(D3:D18) -> 600 | E21: =SUM(E3:E18) -> 1600 | F21: =SUM(F3:F18) -> 0 | G21: =SUM(G3:G18) -> 0 | H21: =SUM(H3:H18) -> 300 | I21: =SUM(I3:I18) -> 150 | J21: =SUM(J3:J18) -> 0 | ... AC21: =SUM(AC3:AC18) -> 0 | AE21: =SUM(AE3:AE18) -> 8110
C22: =CONCATENATE(C2,C21) -> Massa 3900 | D22: =CONCATENATE(D2,D21) -> Molho de tomate 600 | E22: =CONCATENATE(E2,E21) -> Queijo 1600 | F22: =CONCATENATE(F2,F21) -> Rucula 0 | G22: =CONCATENATE(G2,G21) -> Parma 0 | H22: =CONCATENATE(H2,H21) -> Bacon 300 | I22: =CONCATENATE(I2,I21) -> Cream chease 150 | J22: =CONCATENATE(J2,J21) -> Catupiry 0 | ... AC22: =CONCATENATE(AC2,AC21) -> doce leite0 | AE22: =CONCATENATE(AE2,AE21) -> Total por pizza 8110
B24: lista de ingredientes/quantidade | E24: so colocar a quantidade de pizza aqui para gerar os valores
B25: Ingredientes | C25: total | E25: Tipo | F25: quantidade | G25: votos
B26: =C2 -> Massa | C26: =C21 -> 3900 | E26: Parma com rucula
B27: =D2 -> Molho de tomate | C27: =D21 -> 600 | E27: marguerita | F27: 2
B28: =E2 -> Queijo | C28: =E21 -> 1600 | D28: =C28/base!F3 -> 10.666667 | E28: Corn bacon | F28: 2
B29: Rucula | C29: =F21 -> 0 | E29: philadelfia | F29: 2
B30: Parma | C30: =G21 -> 0 | E30: frango catupiry
B31: Bacon | C31: =H21 -> 300 | D31: =C31/base!I5 -> 4 | E31: Caprese
B32: Cream chease | C32: =I21 -> 150 | E32: banana com nutela | F32: 3
B33: Catupiry | C33: =J21 -> 0 | E33: romeu julieta
B34: Tomate | C34: =K21 -> 280 | D34: =C34/70 -> 4 | E34: calabresa | F34: 2
B35: Manjericão | C35: =L21 -> 100 | E35: zuquine
B36: Milho | C36: =M21 -> 130 | D36: =C36/base!N5 -> 2 | E36: peperoni
B37: Frango | C37: =N21 -> 0 | E37: crotine
B38: Mussarela de bufula | C38: =O21 -> 0 | E38: montandela | F38: 2
B39: Azeitona | C39: =P21 -> 0 | E39: Pernil
B40: nutela | C40: =Q21 -> 450 | E40: fraldinha
B41: banana | C41: =R21 -> 300 | E41: banana doce de leite
B42: goiabada | C42: =S21 -> 0
B43: calabresa | C43: =T21 -> 300
...

Sheet Planilha1
A1: Ingredientes | B1: total | C1: Tipo | D1: quantidade
A2: Massa | B2: 3900 | C2: marguerita | D2: 2
A3: Molho de tomate | B3: 600 | C3: Corn bacon | D3: 2
A4: Queijo | B4: 1600 | C4: philadelfia | D4: 2
A5: Bacon | B5: 300 | C5: banana com nutela | D5: 3
A6: Cream chease | B6: 150 | C6: calabresa | D6: 2
A7: Tomate | B7: 280 | C7: montandela | D7: 2
A8: Manjericão | B8: 100
A9: Milho | B9: 130 | C9: receita massa | E9: metade
A10: nutela | B10: 450 | C10: receita massa | D10: 3900 | E10: 1950
A11: banana | B11: 300 | C11: farinha | D11: 2340 | E11: 1170
A12: calabresa | B12: 300 | C12: agua | D12: 1560 | E12: 780
A13: montandela | B13: 420 | C13: sal | D13: 78 | E13: 39
A14: pistache | B14: 30 | C14: fermento | D14: 4.68 | E14: 2.34
A15: qualhada | B15: 200
